Workbook

Sheet Targets
A1: county | B1: batch | C1: page_type | D1: url | E1: external | F1: notes | G1: verify_status | H1: http_status | I1: final_url | J1: audit_confidence | K1: audit_reason | L1: flag_for_review
A2: Alachua | B2: 1 | C2: homepage | D2: https://www.votealachua.gov | E2: false | F2: SOE homepage via state directory — 'Alachua County' in page; 'Supervisor of Elections' in page; seat 'Gainesville' in page; Florida/FL present; official TLD (.gov); election signals: supervisor of elections, vote-by-mail, voter registration | G2: ok | H2: 200 | J2: confident | K2: [plain] county name 'Alachua' in page; seat 'Gainesville' in page | homepage keywords: supervisor of elections, voter registration, early voting | title="Alachua County Elections, FL | Official Website"
A3: Alachua | B3: 1 | C3: elections | D3: https://www.votealachua.gov/258/Upcoming-Elections | E3: false | F3: found via link "Upcoming Elections" score=45 | G3: ok | H3: 200 | J3: confident | K3: [plain] county name 'Alachua' in page; seat 'Gainesville' in page | elections keywords: upcoming election, election information, election calendar, election | title="Upcoming Elections | Alachua County Elections, FL"
A4: Alachua | B4: 1 | C4: polling | D4: https://www.votealachua.gov/207/Precinct-Voting | E4: false | F4: found via "Where Do I Vote?" score=14 | G4: ok | H4: 200 | J4: confident | K4: [plain] county name 'Alachua' in page; seat 'Gainesville' in page | polling keywords: polling place, precinct finder, where do i vote, polling | title="Precinct Voting | Alachua County Elections, FL"
A5: Alachua | B5: 1 | C5: early_voting | D5: https://www.votealachua.gov/Calendar.aspx?EID=359 | E5: false | F5: found via "2026 Primary Election Early Voting Dates" score=13 [per-election URL — refresh each cycle] | G5: ok | H5: 200 | J5: confident | K5: [plain] county name 'Alachua' in page; seat 'Gainesville' in page | early_voting keywords: early voting | title="Calendar • 2026 Primary Election Early Voting Dates"
A6: Alachua | B6: 1 | C6: results | D6: https://www.votealachua.gov/263/Election-Results | E6: false | F6: found via "Election Results" score=22 | G6: ok | H6: 200 | J6: confident | K6: [plain] county name 'Alachua' in page; seat 'Gainesville' in page | results keywords: election result, unofficial result, canvass, election night | title="Election Results | Alachua County Elections, FL"
A7: Baker | B7: 1 | C7: homepage | D7: https://votebakerfl.gov | E7: false | F7: SOE homepage via state directory — 'Baker County' in page; 'Supervisor of Elections' in page; seat 'Macclenny' in page; Florida/FL present; official TLD (.gov); election signals: supervisor of elections, vote-by-mail, early voting | G7: ok | H7: 200 | J7: confident | K7: [plain] county name 'Baker' in page; seat 'Macclenny' in page | homepage keywords: supervisor of elections, early voting, elections office | title="Baker County Supervisor of Elections � Civic Template"
A8: Baker | B8: 1 | C8: elections | E8: false | F8: GAP: no distinct elections landing page — votebakerfl.gov publishes election info on the SOE homepage (checked nav, /elections/, /upcoming-elections/, /election-information/ all 404) | G8: gap | J8: gap
A9: Baker | B9: 1 | C9: polling | D9: https://votebakerfl.gov/precinct-finder/ | E9: false | F9: found via "Where Do I Vote?" score=20 | G9: ok | H9: 200 | J9: confident | K9: [plain] county name 'Baker' in page; seat 'Macclenny' in page | polling keywords: polling place, precinct finder, where do i vote, polling | title="Baker County Supervisor of Elections"
A10: Baker | B10: 1 | C10: early_voting | D10: https://votebakerfl.gov/early-voting/ | E10: false | F10: found via "Early Voting Dates & location" score=25 | G10: ok | H10: 200 | J10: confident | K10: [plain] county name 'Baker' in page; seat 'Macclenny' in page | early_voting keywords: early voting, early vote | title="Baker County Supervisor of Elections"
A11: Baker | B11: 1 | C11: results | D11: https://votebakerfl.gov/election-night-archive/ | E11: false | F11: found via "Election Results Archive" score=27 | G11: ok | H11: 200 | J11: confident | K11: [plain] county name 'Baker' in page; seat 'Macclenny' in page | results keywords: election result, election night reporting, election night, results | title="Baker County Supervisor of Elections"
A12: Bay | B12: 1 | C12: homepage | D12: https://www.bayvotesfl.gov | E12: false | F12: SOE homepage via state directory — 'Bay County' in page; 'Supervisor of Elections' in page; seat 'Panama City' in page; Florida/FL present; official TLD (.gov); election signals: supervisor of elections, vote by mail, vote-by-mail | G12: ok | H12: 200 | J12: confident | K12: [plain] county name 'Bay' in page; seat 'Panama City' in page | homepage keywords: supervisor of elections, vote by mail, early voting, elections office | title="Bay County Supervisor of Elections | Nina Ward"
A13: Bay | B13: 1 | C13: elections | D13: https://www.bayvotesfl.gov/elections/upcoming-elections/ | E13: false | F13: found via link "All Upcoming Elections" score=35 | G13: ok | H13: 200 | J13: confident | K13: [plain] county name 'Bay' in page; seat 'Panama City' in page | elections keywords: upcoming election, sample ballot, election | title="Upcoming Elections | Bay County Supervisor of Elections"
A14: Bay | B14: 1 | C14: polling | D14: https://www.bayvotesfl.gov/voters/where-to-vote-in-person/ | E14: false | F14: found via "Where to Vote in Person" score=12 | G14: ok | H14: 200 | J14: confident | K14: [plain] county name 'Bay' in page; seat 'Panama City' in page | polling keywords: polling place, where to vote, polling | title="Where to Vote in Person | Bay County Supervisor of Elections"
A15: Bay | B15: 1 | C15: early_voting | D15: https://www.bayvotesfl.gov/events/early-voting-primary-election/ | E15: false | F15: found via "Aug 8, 2026 Early Voting Hours: 10AM-6PM" score=25 | G15: ok | H15: 200 | J15: confident | K15: [plain] county name 'Bay' in page; seat 'Panama City' in page | early_voting keywords: early voting, vote early | title="Early Voting: Primary Election | Bay County Supervisor of Elections"
A16: Bay | B16: 1 | C16: results | D16: https://www.bayvotesfl.gov/elections/election-results/ | E16: false | F16: corrected: discovery picked a canvassing-board schedule announcement; this is the standing election-results page | G16: ok | H16: 200 | J16: confident | K16: [plain] county name 'Bay' in page; seat 'Panama City' in page | results keywords: election result, results | title="Election Results | Bay County Supervisor of Elections"
A17: Bradford | B17: 1 | C17: homepage | D17: https://www.votebradfordfl.gov | E17: false | F17: SOE homepage via state directory — 'Bradford County' in page; 'Supervisor of Elections' in page; seat 'Starke' in page; Florida/FL present; official TLD (.gov); election signals: supervisor of elections, vote by mail, vote-by-mail | G17: ok | H17: 200 | J17: confident | K17: [plain] county name 'Bradford' in page; seat 'Starke' in page | homepage keywords: supervisor of elections, voter registration, vote by mail, early voting | title="Bradford County - Supervisor of Elections"
A18: Bradford | B18: 1 | C18: elections | D18: https://www.votebradfordfl.gov/election/upcoming_elections.php | E18: false | F18: found via link "Upcoming Elections" score=45 | G18: ok | H18: 200 | J18: confident | K18: [plain] county name 'Bradford' in page; seat 'Starke' in page | elections keywords: upcoming election, election information, election date, sample ballot | title="Bradford County - Supervisor of Elections"
A19: Bradford | B19: 1 | C19: polling | D19: https://www.votebradfordfl.gov/voter/polling_locations.php | E19: false | F19: found via "Where do I vote?" score=23 | G19: ok | H19: 200 | J19: confident | K19: [plain] county name 'Bradford' in page; seat 'Starke' in page | polling keywords: polling place, where do i vote, polling | title="Where do I vote?"
A20: Bradford | B20: 1 | C20: early_voting | D20: https://www.votebradfordfl.gov/election/early_voting.php | E20: false | F20: found via "Early Voting" score=12 | G20: ok | H20: 200 | J20: confident | K20: [plain] county name 'Bradford' in page; seat 'Starke' in page | early_voting keywords: early voting | title="Bradford County - Supervisor of Elections"
... A38: Charlotte | B38: 1 | C38: elections | D38: https://www.soecharlottecountyfl.gov/31/Election-Information | E38: false | F38: found via link "Election Information" score=21 | G38: ok | H38: 200 | J38: confident | K38: [plain] county name 'Charlotte' in page; seat 'Punta Gorda' in page | elections keywords: election information, election | title="Election Information | Charlotte County Elections, FL"
A39: Charlotte | B39: 1 | C39: polling | E39: false | F39: GAP: candidate is non-HTML (application/pdf) — out of scope | G39: gap | J39: gap | K39: GAP: candidate is non-HTML (application/pdf) — out of scope
A40: Charlotte | B40: 1 | C40: early_voting | D40: https://www.soecharlottecountyfl.gov/1315/Early-Voting-Locations | E40: false | F40: found via "Early Voting Locations" score=27 | G40: ok | H40: 200 | J40: confident | K40: [plain] county name 'Charlotte' in page; seat 'Punta Gorda' in page | early_voting keywords: early voting | title="Early Voting Locations | Charlotte County Elections, FL"
A41: Charlotte | B41: 1 | C41: results | E41: false | F41: GAP: no distinct page found (likely folded into elections page) | G41: gap | J41: gap | K41: GAP: no distinct page found (likely folded into elections page)
A42: Citrus | B42: 1 | C42: homepage | D42: https://www.votecitrus.gov | E42: false | F42: SOE homepage via state directory — 'Citrus County' in page; 'Supervisor of Elections' in page; SOE office city 'Lecanto' in page; Florida/FL present; official TLD (.gov); election signals: supervisor of elections, vote by mail, vote-by-mail | G42: ok | H42: 200 | J42: confident | K42: [plain] county name 'Citrus' in page; SOE office city 'Lecanto' in page | homepage keywords: supervisor of elections, voter registration, vote by mail, early voting | title="Citrus County Elections, FL | Official Website"
A43: Citrus | B43: 1 | C43: elections | D43: https://www.votecitrus.gov/171/Election-Information | E43: false | F43: found via link "Election Information" score=21 | G43: ok | H43: 200 | J43: confident | K43: [plain] county name 'Citrus' in page; SOE office city 'Lecanto' in page | elections keywords: election information, sample ballot, election | title="Election Information | Citrus County Elections, FL"
A44: Citrus | B44: 1 | C44: polling | D44: https://www.votecitrus.gov/229/Precinct-Locations | E44: false | F44: corrected: discovery fell back to a per-election hub; this is the standing precinct/polling locations page | G44: ok | H44: 200 | J44: confident | K44: [plain] county name 'Citrus' in page; seat 'Inverness' in page | polling keywords: polling location, precinct finder, where do i vote, polling | title="Precinct Locations | Citrus County Elections, FL"
A45: Citrus | B45: 1 | C45: early_voting | D45: https://www.votecitrus.gov/238/2026-Early-Voting-Sites-Schedule | E45: false | F45: found via "2026 Early Voting Sites & Schedule" score=27 | G45: ok | H45: 200 | J45: confident | K45: [plain] county name 'Citrus' in page; seat 'Inverness' in page | early_voting keywords: early voting, early vote | title="2026 Early Voting Sites & Schedule | Citrus County Elections, FL"
A46: Citrus | B46: 1 | C46: results | D46: https://www.votecitrus.gov/193/Election-Results-1992-to-2026 | E46: false | F46: found via "Election Results 1992 to 2026" score=22 | G46: ok | H46: 200 | J46: confident | K46: [plain] county name 'Citrus' in page; seat 'Inverness' in page | results keywords: election result, results | title="Election Results 1992 to 2026 | Citrus County Elections, FL"
A47: Clay | B47: 1 | C47: homepage | D47: https://clayelections.gov/ | E47: false | F47: SOE homepage via state directory — 'Clay County' in page; 'Supervisor of Elections' in page; seat 'Green Cove Springs' in page; Florida/FL present; official TLD (.gov); election signals: supervisor of elections, vote by mail, voter registration | G47: ok | H47: 200 | J47: confident | K47: [plain] county name 'Clay' in page; seat 'Green Cove Springs' in page | homepage keywords: supervisor of elections, voter registration, vote by mail, early voting | title="Clay County Supervisor of Elections"
A48: Clay | B48: 1 | C48: elections | D48: https://clayelections.gov/event_type/elections/ | E48: false | F48: found via link "Upcoming Elections" score=45 | G48: ok | H48: 200 | J48: confident | K48: [plain] county name 'Clay' in page; seat 'Green Cove Springs' in page | elections keywords: upcoming election, election information, election | title="Elections Archives - Clay County Supervisor of Elections"
A49: Clay | B49: 1 | C49: polling | D49: https://clayelections.gov/Election-Information/Precinct-Finder/ | E49: false | F49: found via "Where Do I Vote?" score=20 | G49: ok | H49: 200 | J49: confident | K49: [plain] county name 'Clay' in page; seat 'Green Cove Springs' in page | polling keywords: precinct finder, where to vote | title="Precinct Finder - Clay County Supervisor of Elections"
A50: Clay | B50: 1 | C50: early_voting | D50: https://clayelections.gov/election-information/early-voting-sites/ | E50: false | F50: found via "Early Voting Sites" score=27 | G50: ok | H50: 200 | J50: confident | K50: [plain] county name 'Clay' in page; seat 'Green Cove Springs' in page | early_voting keywords: early voting | title="Early Voting Sites - Clay County Supervisor of Elections"
A51: Clay | B51: 1 | C51: results | D51: https://clayelections.gov/results/ | E51: false | F51: found via "View Election Results" score=22 | G51: ok | H51: 200 | J51: confident | K51: [plain] county name 'Clay' in page; seat 'Green Cove Springs' in page | results keywords: election result, results | title="Results - Clay County Supervisor of Elections"
A52: Collier | B52: 1 | C52: homepage | D52: https://www.colliervotes.gov | E52: false | F52: SOE homepage via state directory — 'Collier County' in page; 'Supervisor of Elections' in page; seat 'Naples' in page; Florida/FL present; official TLD (.gov); election signals: supervisor of elections, vote by mail, vote-by-mail | G52: ok | H52: 200 | J52: confident | K52: [plain] county name 'Collier' in page; seat 'Naples' in page | homepage keywords: supervisor of elections, voter registration, vote by mail, early voting | title="Collier County Elections, FL | Official Website"
A53: Collier | B53: 1 | C53: elections | D53: https://www.colliervotes.gov/308/Upcoming-Elections | E53: false | F53: found via link "Upcoming Elections" score=45 | G53: ok | H53: 200 | J53: confident | K53: [plain] county name 'Collier' in page; seat 'Naples' in page | elections keywords: upcoming election, election date, election | title="Upcoming Elections | Collier County Elections, FL"
... A55: Collier | B55: 1 | C55: early_voting | D55: https://www.colliervotes.gov/202/Vote-Early | E55: false | F55: found via "Find An Early Voting Location" score=32 | G55: ok | H55: 200 | J55: confident | K55: [plain] county name 'Collier' in page; seat 'Naples' in page | early_voting keywords: early voting, vote early | title="Vote Early | Collier County Elections, FL"
A56: Collier | B56: 1 | C56: results | E56: false | F56: GAP: no distinct page found (likely folded into elections page) | G56: gap | J56: gap | K56: GAP: no distinct page found (likely folded into elections page)
A57: Columbia | B57: 1 | C57: homepage | D57: https://www.votecolumbiafl.gov | E57: false | F57: SOE homepage via state directory — 'Columbia County' in page; 'Supervisor of Elections' in page; seat 'Lake City' in page; Florida/FL present; official TLD (.gov); election signals: supervisor of elections, vote by mail, vote-by-mail | G57: ok | H57: 200 | J57: confident | K57: [plain] county name 'Columbia' in page; seat 'Lake City' in page | homepage keywords: supervisor of elections, voter registration, vote by mail, early voting | title="Columbia County Supervisor of Elections, FL"
A58: Columbia | B58: 1 | C58: elections | D58: https://www.votecolumbiafl.gov/election_information/upcoming_elections.php | E58: false | F58: found via link "Upcoming Elections" score=46 | G58: ok | H58: 200 | J58: confident | K58: [plain] county name 'Columbia' in page; seat 'Lake City' in page | elections keywords: upcoming election, election information, election | title="Columbia County Supervisor of Elections, FL"
...

Sheet Counties
A1: county | B1: seat | C1: office_city | D1: batch | E1: homepage
A2: Alachua | B2: Gainesville | C2: Gainesville | D2: 1 | E2: https://www.votealachua.gov
A3: Baker | B3: Macclenny | C3: Macclenny | D3: 1 | E3: https://votebakerfl.gov
A4: Bay | B4: Panama City | C4: Panama City | D4: 1 | E4: https://www.bayvotesfl.gov
A5: Bradford | B5: Starke | C5: Starke | D5: 1 | E5: https://www.votebradfordfl.gov
A6: Brevard | B6: Titusville | C6: Melbourne | D6: 1 | E6: https://www.votebrevard.gov
A7: Broward | B7: Fort Lauderdale | C7: Fort Lauderdale | D7: 1 | E7: https://browardvotes.gov/
A8: Calhoun | B8: Blountstown | C8: Blountstown | D8: 1 | E8: https://votecalhounfl.gov/
A9: Charlotte | B9: Punta Gorda | C9: Punta Gorda | D9: 1 | E9: https://www.soecharlottecountyfl.gov
A10: Citrus | B10: Inverness | C10: Lecanto | D10: 1 | E10: https://www.votecitrus.gov
A11: Clay | B11: Green Cove Springs | C11: Green Cove Springs | D11: 1 | E11: https://clayelections.gov/
A12: Collier | B12: Naples | C12: Naples | D12: 1 | E12: https://www.colliervotes.gov
... A68: Washington | B68: Chipley | C68: Chipley | D68: 1 | E68: https://wcsoe.gov/

Sheet Coverage
A1: Coverage by page type
A3: page_type | B3: captured | C3: gaps | D3: total | E3: % captured
A4: homepage | B4: =COUNTIFS(Targets!$C$2:$C$336,$A4,Targets!$D$2:$D$336,"?*") | C4: =D4-B4 | D4: =COUNTIF(Targets!$C$2:$C$336,$A4) | E4: =IFERROR(B4/D4,0)
A5: elections | B5: =COUNTIFS(Targets!$C$2:$C$336,$A5,Targets!$D$2:$D$336,"?*") | C5: =D5-B5 | D5: =COUNTIF(Targets!$C$2:$C$336,$A5) | E5: =IFERROR(B5/D5,0)
A6: polling | B6: =COUNTIFS(Targets!$C$2:$C$336,$A6,Targets!$D$2:$D$336,"?*") | C6: =D6-B6 | D6: =COUNTIF(Targets!$C$2:$C$336,$A6) | E6: =IFERROR(B6/D6,0)
A7: early_voting | B7: =COUNTIFS(Targets!$C$2:$C$336,$A7,Targets!$D$2:$D$336,"?*") | C7: =D7-B7 | D7: =COUNTIF(Targets!$C$2:$C$336,$A7) | E7: =IFERROR(B7/D7,0)
A8: results | B8: =COUNTIFS(Targets!$C$2:$C$336,$A8,Targets!$D$2:$D$336,"?*") | C8: =D8-B8 | D8: =COUNTIF(Targets!$C$2:$C$336,$A8) | E8: =IFERROR(B8/D8,0)
A9: TOTAL | B9: =SUM(B4:B8) | C9: =SUM(C4:C8) | D9: =SUM(D4:D8) | E9: =IFERROR(B9/D9,0)
A11: Counties by number of page types captured
A13: pages captured | B13: counties
A14: 5 of 5 | B14: 50
A15: 4 of 5 | B15: 13
A16: 3 of 5 | B16: 4
A18: Note: this second table is a static count taken at export time (a per-county tally would need a helper column). The table above is live formulas.

Sheet Legend
A1: fl-county-watch — manifest columns
A3: county | B3: Florida county name, as it appears everywhere else in the project.
A4: batch | B4: Where this county's SOE homepage came from. 1 = the Florida DOS Supervisor of Elections directory, as published. 2 = that directory URL was stale, and the live domain was resolved and verified instead.
A5: page_type | B5: homepage (SOE front page) · elections · polling · early_voting · results.
A6: url | B6: The page that gets snapshotted. EMPTY = a recorded gap; the reason is in notes.
A7: external | B7: true when the URL's registered domain differs from the SOE homepage's — typically a third-party results portal.
A8: notes | B8: Provenance: how the URL was found, why a row is a gap, or the human QA judgement ('corrected:' / 'verified:').
A9: verify_status | B9: ok (live) · broken (4xx/5xx/error/non-HTML) · gap (no URL).
A10: http_status | B10: HTTP status of the final response.
A11: final_url | B11: Filled only when the request redirected elsewhere.
A12: audit_confidence | B12: confident · likely · uncertain · broken · gap — whether the fetched content really is this county's page of this type.
A13: audit_reason | B13: Which identity and page-type keywords matched, plus the page title.
A14: flag_for_review | B14: yes when a human should eyeball the row.
A16: Colours
A17: confident | B17: green — identity and page-type signals both matched
A18: likely | B18: amber — matched, but with a weaker signal
A19: uncertain | B19: red — needs a human look
A20: broken | B20: strong red — the URL did not serve a usable page
A21: gap row | B21: whole row grey — no URL for this page type; see notes
A23: Source of truth | B23: manifest/targets.csv. This workbook is GENERATED by scripts/export_xlsx.py — edit the CSV and re-run, never edit here.
